Workbook

Sheet Hoja1
A1: Set de datos: | B1: Data CS 25 SUC. IVAN VALDES estanque 239
B2: Método opt. global | C2: Parámetros opt. | G2: ¿least _square (ls)? | H2: Costo final opt. | I2: Costo final ls | J2: Tiempo (s) | L2: de y da tienen seed 50 siempre
C3: maxiter | D3: popsize | E3: n_particles (pop_size) | F3: n_iter (epoch) | L3: de y da tienen optimización local activada en su interna
B4: differential evolution | C4: 8 | D4: 4 | G4: No | H4: 82.549381 | J4: 19.95
B5: differential evolution | C5: 8 | D5: 6 | G5: No | H5: 204.12437 | J5: 16.18
B6: differential evolution | C6: 8 | D6: 8 | G6: No | H6: 538.6583 | J6: 28.18
B7: differential evolution | C7: 14 | D7: 4 | G7: No | H7: 81.804288 | J7: 46.52
B8: differential evolution | C8: 14 | D8: 6 | G8: No | H8: 84.980455 | J8: 24.79
B9: differential evolution | C9: 14 | D9: 8 | G9: No | H9: 55.27013 | J9: 42.3
B10: differential evolution | C10: 20 | D10: 4 | G10: No | H10: 81.842918 | J10: =60+7.47 -> 67.47
B11: differential evolution | C11: 20 | D11: 6 | G11: No | H11: 63.049161 | J11: 59.3
B12: differential evolution | C12: 20 | D12: 8 | G12: No | H12: 93.389412 | J12: 55.53
B13: differential evolution | C13: 8 | D13: 4 | G13: Si | H13: 82.549381 | I13: 82.325163 | J13: 21.41
B14: differential evolution | C14: 8 | D14: 6 | G14: Si | H14: 204.12437 | I14: 204.12434 | J14: 17.03
B15: differential evolution | C15: 8 | D15: 8 | G15: Si | H15: 538.6583 | I15: 84.173643 | J15: 31.45
B16: differential evolution | C16: 14 | D16: 4 | G16: Si | H16: 81.804288 | I16: 81.804279 | J16: 41.68
B17: differential evolution | C17: 14 | D17: 6 | G17: Si | H17: 84.980455 | I17: 84.750533 | J17: 25.76
B18: differential evolution | C18: 14 | D18: 8 | G18: Si | H18: 55.27013 | I18: 55.270099 | J18: 38.05
B19: differential evolution | C19: 20 | D19: 4 | G19: Si | H19: 81.842918 | I19: 81.842918 | J19: 48.2
B20: differential evolution | C20: 20 | D20: 6 | G20: Si | H20: 63.049161 | I20: 58.249422 | J20: 49.94
B21: differential evolution | C21: 20 | D21: 8 | G21: Si | H21: 93.389412 | I21: 67.115604 | J21: 57.4
B22: dual annealing | C22: 10 | G22: No | H22: 59.072205 | J22: 17.58
B23: dual annealing | C23: 20 | G23: No | H23: 59.072205 | J23: 21.11
B24: dual annealing | C24: 40 | G24: No | H24: 59.072205 | J24: 25.03
B25: dual annealing | C25: 60 | G25: No | H25: 59.072205 | J25: 31.68
B26: dual annealing | C26: 10 | G26: Si | H26: 59.072205 | I26: 59.063559 | J26: 17.51
B27: dual annealing | C27: 20 | G27: Si | H27: 59.072205 | I27: 59.063559 | J27: 20.59
B28: dual annealing | C28: 40 | G28: Si | H28: 59.072205 | I28: 59.063559 | J28: 26.71
B29: dual annealing | C29: 60 | G29: Si | H29: 59.072205 | I29: 59.063559 | J29: 33.34
B30: PSO | E30: 10 | F30: 50 | G30: No | H30: 76.496085 | J30: 12.17
B31: PSO | E31: 15 | F31: 50 | G31: No | H31: 34.156917 | J31: 15.71
B32: PSO | E32: 20 | F32: 50 | G32: No | H32: 21.866986 | J32: 16.81
B33: PSO | E33: 25 | F33: 50 | G33: No | H33: 21.598196 | J33: 23.94
B34: PSO | E34: 10 | F34: 80 | G34: No | H34: 68.838314 | J34: 19.32
B35: PSO | E35: 15 | F35: 80 | G35: No | H35: 33.38398 | J35: 26.42
B36: PSO | E36: 20 | F36: 80 | G36: No | H36: 21.11547 | J36: 25.24
B37: PSO | E37: 25 | F37: 80 | G37: No | H37: 21.152551 | J37: 30.22
B38: PSO | E38: 25 | F38: 100 | G38: No | H38: 21.096196 | J38: 47.07
B39: PSO | E39: 25 | F39: 150 | G39: No | H39: 20.933555 | J39: 63.35
B40: PSO | E40: 25 | F40: 80 | G40: Si | H40: 21.152551 | I40: 21.151507 | J40: 29.78
...

Sheet Hoja2
A1: Set de datos: | B1: Data CS 25 SUC. IVAN VALDES estanque 239 | N1: PROBAR CON C1 = 1,5, C2 = 1,5 y w = 0,7
B2: Método opt. global | C2: Parámetros opt. | G2: Costo final opt. | H2: Tiempo (s) | I2: Tiempo (min) | N2: Set de datos | O2: Método opt. global | P2: Parámetros opt. | T2: Costo final opt. | U2: Tiempo (s) | V2: Tiempo (min)
C3: maxiter | D3: popsize | E3: n_particles (pop_size) | F3: n_iter (epoch) | P3: maxiter | Q3: popsize | R3: n_particles (pop_size) | S3: n_iter (epoch)
B4: PSO | E4: 25 | F4: 150 | G4: 0.00035405915 | H4: =60+18.28 -> 78.28 | I4: =H4/60 -> 1.3046667 | N4: Data CS 25 SUC. IVAN VALDES estanque 239 | O4: PSO | R4: 25 | S4: 200 | T4: =G5 -> 0.00035386864 | U4: =H5 -> 84.3 | V4: =I5 -> 1.405
B5: PSO | E5: 25 | F5: 200 | G5: 0.00035386864 | H5: =60+24.3 -> 84.3 | I5: =H5/60 -> 1.405 | O5: PSO mealpy pso.originalpso | R5: 25 | S5: 10000, eps = 1e-7 | T5: 0.0013251363 | U5: =6*60+41.95 -> 401.95 | V5: =U5/60 -> 6.6991667 | W5: Debe ser más exigente el criterio para cortar optimización
I6: =H6/60 -> 0
B7: PSO mealpy pso.originalpso | E7: 25 | F7: 150 | G7: 0.00074729873 | H7: =60+39.4 -> 99.4 | I7: =H7/60 -> 1.6566667 | N7: Data CS 24 AGROCAUQ estanque 68.xlsx | O7: PSO | R7: 25 | S7: 500 | T7: =G25 -> 0.011013753 | U7: =H25 -> 983.38 | V7: =I25 -> 16.389667
B8: PSO mealpy pso.originalpso | E8: 25 | F8: 200 | G8: 0.00074539463 | H8: =60*2+16.43 -> 136.43 | I8: =H8/60 -> 2.2738333 | O8: PSO mealpy pso.originalpso | W8: Mas de una hora corriendo
B9: PSO mealpy pso.originalpso | E9: 20 | F9: 10000, eps = 1e-6 | G9: 0.00071734288 | H9: =4*60+58.9 -> 298.9 | I9: =H9/60 -> 4.9816667 | J9: con termination en it = 113
B10: differential evolution | C10: 14 | D10: 8 | G10: 0.0010140708 | H10: 23.59 | I10: =H10/60 -> 0.39316667 | N10: Data CS 24 LOU estanque 54.xlsx | O10: PSO | R10: 25 | S10: 200 | T10: =G43 -> 0.00049637377 | U10: =H43 -> 297.94 | V10: =I43 -> 4.9656667
B11: differential evolution | C11: 20 | D11: 8 | G11: 0.0026214963 | H11: 35.13 | I11: =H11/60 -> 0.5855 | O11: PSO mealpy pso.originalpso
B12: differential evolution | C12: 50 | D12: 10 | G12: 0.00072968812 | H12: =60+39.66 -> 99.66 | I12: =H12/60 -> 1.661
B13: dual annealing | C13: 20 | G13: 0.029707313 | H13: 23.9 | I13: =H13/60 -> 0.39833333
B14: dual annealing | C14: 50 | G14: 0.0032673059 | H14: 50.34 | I14: =H14/60 -> 0.839
G16: =MIN(G4:G14) -> 0.00035386864
A20: Set de datos: | B20: Data CS 24 AGROCAUQ estanque 68.xlsx
B21: Método opt. global | C21: Parámetros opt. | G21: Costo final opt. | H21: Tiempo (s) | I21: Tiempo (min)
C22: maxiter | D22: popsize | E22: n_particles (pop_size) | F22: n_iter (epoch)
B23: PSO | E23: 25 | F23: 150 | G23: 0.01102279 | H23: =3*60+59.05 -> 239.05 | I23: =H23/60 -> 3.9841667
B24: PSO | E24: 25 | F24: 200 | G24: 0.011022084 | H24: =5*60+36.45 -> 336.45 | I24: =H24/60 -> 5.6075
B25: PSO | E25: 25 | F25: 500 | G25: 0.011013753 | H25: =16*60+23.38 -> 983.38 | I25: =H25/60 -> 16.389667
B27: PSO mealpy pso.originalpso | E27: 25 | F27: 150 | G27: 0.050054474 | H27: =2*60+57.09 -> 177.09 | I27: =H27/60 -> 2.9515
B28: PSO mealpy pso.originalpso | E28: 25 | F28: 200 | G28: 0.0083019029 | H28: =4*60+16.62 -> 256.62 | I28: =H28/60 -> 4.277
B29: PSO mealpy pso.originalpso | E29: 20 | F29: 10000, eps = 1e-6 | G29: 0.0013403521 | H29: =5*60+36.08 -> 336.08 | I29: =H29/60 -> 5.6013333 | J29: con termination en it = 219
I30: =H30/60 -> 0
I31: =H31/60 -> 0
B32: dual annealing | C32: 50 | G32: 0.014277277 | H32: =60+48.03 -> 108.03 | I32: =H32/60 -> 1.8005 | K32: Dual annealing funciona peor con esta función objetivo
I33: =H33/60 -> 0
I34: =H34/60 -> 0
G35: =MIN(G23:G34) -> 0.0013403521
A39: Set de datos: | B39: Data CS 24 LOU estanque 54.xlsx
B40: Método opt. global | C40: Parámetros opt. | G40: Costo final opt. | H40: Tiempo (s) | I40: Tiempo (min)
C41: maxiter | D41: popsize | E41: n_particles (pop_size) | F41: n_iter (epoch)
B42: PSO | E42: 25 | F42: 150 | G42: 0.00049674921 | H42: =3*60+30.56 -> 210.56 | I42: =H42/60 -> 3.5093333
B43: PSO | E43: 25 | F43: 200 | G43: 0.00049637377 | H43: =4*60+57.94 -> 297.94 | I43: =H43/60 -> 4.9656667
B44: PSO mealpy pso.originalpso | E44: 20 | F44: 10000, eps = 1e-6 | G44: 0.00053459457 | H44: =11*60+36.44 -> 696.44 | I44: =H44/60 -> 11.607333 | J44: con termination en it = 129
G46: =MIN(G42:G44) -> 0.00049637377

Sheet Pruebas PSO
C1: Parámetros opt. | K1: Parámetros | Z1: Parámetros fijados
A2: Set de datos | B2: Método PSO | C2: epoch | D2: pop_size | E2: c1 | F2: c2 | G2: w | H2: Costo final opt. | I2: Tiempo (s) | J2: Tiempo (min) | K2: mu0 | L2: betaG0 | M2: betaF0 | N2: Kn0 | O2: Kg0 | P2: Kf0 | Q2: Kig0 | R2: Kie0 | S2: Kd0 | T2: Yxn | U2: Yxg | V2: Yxf | W2: Yeg | X2: Yef
A3: 1. Data CS 25 SUC. IVAN VALDES estanque 239 | B3: PSO_gpt | C3: 150 | D3: 20 | E3: 1.5 | F3: 1.5 | G3: 0.7 | H3: 0.00029472176 | I3: =60+13.49 -> 73.49 | J3: =I3/60 -> 1.2248333 | K3: 0.021924339 | L3: 5.3243125 | M3: 10 | N3: 0.009647 | O3: 8.551854 | P3: 7.16565 | Q3: 44.15067 | R3: 42.528284 | S3: 0.0001 | T3: 2.1598444 | U3: 9.4242283 | V3: 1.642634 | W3: 0.1 | X3: 0.66937281
A4: 1. Data CS 25 SUC. IVAN VALDES estanque 239 | B4: PSO_pyswarms | C4: 150 | D4: 20 | E4: 1.5 | F4: 1.5 | G4: 0.7 | H4: 0.023513881 | I4: =60+7.64 -> 67.64 | J4: =I4/60 -> 1.1273333 | K4: 6.9239735 | L4: 1.820781 | M4: 9.9329325 | N4: 0.009647 | O4: 8.551854 | P4: 7.16565 | Q4: 44.15067 | R4: 42.528284 | S4: 0.0001 | T4: 2.2496431 | U4: 3.9014864 | V4: 1.642634 | W4: 1.4863469 | X4: 0.2673638
A5: 1. Data CS 25 SUC. IVAN VALDES estanque 239 | B5: PSO_mealpy | C5: 150 | D5: 20 | E5: 1.5 | F5: 1.5 | G5: 0.7 | H5: 0.0013270129 | I5: =5*60+48.41 -> 348.41 | J5: =I5/60 -> 5.8068333 | K5: 3.0051334 | L5: 5.0528684 | M5: 4.8710938 | N5: 0.009647 | O5: 8.551854 | P5: 7.16565 | Q5: 44.15067 | R5: 42.528284 | S5: 0.0001 | T5: 1.0681248 | U5: 3.3029168 | V5: 1.642634 | W5: 0.29242188 | X5: 0.47648837
A6: 1. Data CS 25 SUC. IVAN VALDES estanque 239 | B6: PSO_pymoo | C6: 150 | D6: 20 | E6: 1.5 | F6: 1.5 | G6: 0.7 | H6: 0.00070487363 | I6: =60+14.51 -> 74.51 | J6: =I6/60 -> 1.2418333 | K6: 0.23210223 | L6: 4.129707 | M6: 6.0078738 | N6: 0.009647 | O6: 8.551854 | P6: 7.16565 | Q6: 44.15067 | R6: 42.528284 | S6: 0.0001 | T6: 1.1019035 | U6: 2.9727656 | V6: 1.642634 | W6: 0.20748441 | X6: 0.59401553
A7: 1. Data CS 25 SUC. IVAN VALDES estanque 239 | B7: PSO_gpt | C7: 200 | D7: 20 | E7: 1.5 | F7: 1.5 | G7: 0.7 | H7: 0.00029328842 | I7: =60+15.12 -> 75.12 | J7: =I7/60 -> 1.252 | K7: 0.021763903 | L7: 5.3320006 | M7: 10 | N7: 0.009647 | O7: 8.551854 | P7: 7.16565 | Q7: 44.15067 | R7: 42.528284 | S7: 0.0001 | T7: 2.7464837 | U7: 9.4217689 | V7: 1.642634 | W7: 0.1 | X7: 0.66954694
A8: 1. Data CS 25 SUC. IVAN VALDES estanque 239 | B8: PSO_pyswarms | C8: 200 | D8: 20 | E8: 1.5 | F8: 1.5 | G8: 0.7 | H8: 0.023513881 | I8: =60+31.97 -> 91.97 | J8: =I8/60 -> 1.5328333 | K8: 6.9239735 | L8: 1.820781 | M8: 9.9329325 | N8: 0.009647 | O8: 8.551854 | P8: 7.16565 | Q8: 44.15067 | R8: 42.528284 | S8: 0.0001 | T8: 2.2496431 | U8: 3.9014864 | V8: 1.642634 | W8: 1.4863469 | X8: 0.2673638
A9: 1. Data CS 25 SUC. IVAN VALDES estanque 239 | B9: PSO_mealpy | C9: 200 | D9: 20 | E9: 1.5 | F9: 1.5 | G9: 0.7 | H9: 0.0013251363 | I9: =60*7+25.26 -> 445.26 | J9: =I9/60 -> 7.421 | K9: 3.0150652 | L9: 5.0592534 | M9: 4.868728 | N9: 0.009647 | O9: 8.551854 | P9: 7.16565 | Q9: 44.15067 | R9: 42.528284 | S9: 0.0001 | T9: 1.067929 | U9: 3.3038454 | V9: 1.642634 | W9: 0.29253732 | X9: 0.47645758
A10: 1. Data CS 25 SUC. IVAN VALDES estanque 239 | B10: PSO_pymoo | C10: 200 | D10: 20 | E10: 1.5 | F10: 1.5 | G10: 0.7 | H10: 0.00070424314 | I10: =60+30.12 -> 90.12 | J10: =I10/60 -> 1.502 | K10: 0.23198883 | L10: 4.1316374 | M10: 6.0033822 | N10: 0.009647 | O10: 8.551854 | P10: 7.16565 | Q10: 44.15067 | R10: 42.528284 | S10: 0.0001 | T10: 1.1016421 | U10: 3.1223847 | V10: 1.642634 | W10: 0.207547 | X10: 0.59565351
A11: 1. Data CS 25 SUC. IVAN VALDES estanque 239 | B11: PSO_gpt | C11: 500 | D11: 20 | E11: 1.5 | F11: 1.5 | G11: 0.7 | H11: 0.00029106328 | I11: =3*60+9.3 -> 189.3 | J11: =I11/60 -> 3.155 | K11: 0.021502309 | L11: 5.3545334 | M11: 10 | N11: 0.009647 | O11: 8.551854 | P11: 7.16565 | Q11: 44.15067 | R11: 42.528284 | S11: 0.0001 | T11: 10 | U11: 9.5278443 | V11: 1.642634 | W11: 0.1 | X11: 0.66792359
A12: 1. Data CS 25 SUC. IVAN VALDES estanque 239 | B12: PSO_pyswarms | C12: 500 | D12: 20 | E12: 1.5 | F12: 1.5 | G12: 0.7 | H12: 0.012479497 | I12: =3*60+43.91 -> 223.91 | J12: =I12/60 -> 3.7318333 | K12: 5.0791991 | L12: 3.6404145 | M12: 5.9324972 | N12: 0.009647 | O12: 8.551854 | P12: 7.16565 | Q12: 44.15067 | R12: 42.528284 | S12: 0.0001 | T12: 1.6798296 | U12: 3.9528445 | V12: 1.642634 | W12: 1.4831927 | X12: 0.10854293
A13: 1. Data CS 25 SUC. IVAN VALDES estanque 239 | B13: PSO_mealpy | C13: 500 | D13: 20 | E13: 1.5 | F13: 1.5 | G13: 0.7 | H13: 0.001228286 | I13: =20*60+26.29 -> 1226.29 | J13: =I13/60 -> 20.438167 | K13: 1.1057744 | L13: 7.8360003 | M13: 1.6052789 | N13: 0.009647 | O13: 8.551854 | P13: 7.16565 | Q13: 44.15067 | R13: 42.528284 | S13: 0.0001 | T13: 1.2822673 | U13: 0.6524855 | V13: 1.642634 | W13: 0.51457519 | X13: 0.1442842
A14: 1. Data CS 25 SUC. IVAN VALDES estanque 239 | B14: PSO_pymoo | C14: 500 | D14: 20 | E14: 1.5 | F14: 1.5 | G14: 0.7 | H14: 0.00070311621 | I14: =4*60+9.5 -> 249.5 | J14: =I14/60 -> 4.1583333 | K14: 0.23027793 | L14: 4.1471161 | M14: 6.0025563 | N14: 0.009647 | O14: 8.551854 | P14: 7.16565 | Q14: 44.15067 | R14: 42.528284 | S14: 0.0001 | T14: 1.1015287 | U14: 2.4944333 | V14: 1.642634 | W14: 0.20757537 | X14: 0.59564623
A15: 1. Data CS 25 SUC. IVAN VALDES estanque 239 | B15: PSO_pymoo | C15: 500 | D15: 25 | E15: 1.5 | F15: 1.5 | G15: 0.7 | H15: 0.00067861315 | I15: =4*60+45.45 -> 285.45 | J15: =I15/60 -> 4.7575 | K15: 0.65584707 | L15: 1.6542627 | M15: 0.93599323 | N15: 0.009647 | O15: 8.551854 | P15: 7.16565 | Q15: 44.15067 | R15: 42.528284 | S15: 0.0001 | T15: 6.3300111 | U15: 0.97696229 | V15: 1.642634 | W15: 0.35156639 | X15: 0.40093323
A16: 2. Data CS 24 AGROCAUQ estanque 68.xlsx | B16: PSO_gpt | C16: 150 | D16: 20 | E16: 1.5 | F16: 1.5 | G16: 0.7 | H16: 0.011144062 | I16: =4*60+18.28 -> 258.28 | J16: =I16/60 -> 4.3046667 | K16: 2.3299382 | L16: 5.3228702 | M16: 7.982432 | N16: 0.009647 | O16: 8.551854 | P16: 7.16565 | Q16: 44.15067 | R16: 42.528284 | S16: 0.0001 | T16: 0.17054697 | U16: 7.0897164 | V16: 1.642634 | W16: 0.47501879 | X16: 0.34154453
A17: 2. Data CS 24 AGROCAUQ estanque 68.xlsx | B17: PSO_pyswarms | C17: 150 | D17: 20 | E17: 1.5 | F17: 1.5 | G17: 0.7 | H17: 0.033679725 | I17: =2*60+53.1 -> 173.1 | J17: =I17/60 -> 2.885 | K17: 3.8814632 | L17: 2.8667226 | M17: 6.8650101 | N17: 0.009647 | O17: 8.551854 | P17: 7.16565 | Q17: 44.15067 | R17: 42.528284 | S17: 0.0001 | T17: 1.1602649 | U17: 5.8389023 | V17: 1.642634 | W17: 0.64665747 | X17: 0.20406756
A18: 2. Data CS 24 AGROCAUQ estanque 68.xlsx | B18: PSO_mealpy | C18: 150 | D18: 20 | E18: 1.5 | F18: 1.5 | G18: 0.7 | H18: 0.011535923 | I18: =31*60+32.58 -> 1892.58 | J18: =I18/60 -> 31.543 | K18: 4.6612648 | L18: 7.6274459 | M18: 3.9388701 | N18: 0.009647 | O18: 8.551854 | P18: 7.16565 | Q18: 44.15067 | R18: 42.528284 | S18: 0.0001 | T18: 0.17179967 | U18: 4.8454643 | V18: 1.642634 | W18: 0.71125672 | X18: 0.1368129
A19: 2. Data CS 24 AGROCAUQ estanque 68.xlsx | B19: PSO_pymoo | C19: 150 | D19: 20 | E19: 1.5 | F19: 1.5 | G19: 0.7 | H19: 0.0011953798 | I19: =5*60+28.86 -> 328.86 | J19: =I19/60 -> 5.481 | K19: 0.086968657 | L19: 0.37972652 | M19: 1.8859295 | N19: 0.009647 | O19: 8.551854 | P19: 7.16565 | Q19: 44.15067 | R19: 42.528284 | S19: 0.0001 | T19: 9.2643799 | U19: 9.9263325 | V19: 1.642634 | W19: 0.14259671 | X19: 0.67266227
A20: 2. Data CS 24 AGROCAUQ estanque 68.xlsx | B20: PSO_gpt | C20: 200 | D20: 20 | E20: 1.5 | F20: 1.5 | G20: 0.7 | H20: 0.011136768 | I20: =5*60+3.26 -> 303.26 | J20: =I20/60 -> 5.0543333 | K20: 2.4041884 | L20: 5.3229813 | M20: 8.0155018 | N20: 0.009647 | O20: 8.551854 | P20: 7.16565 | Q20: 44.15067 | R20: 42.528284 | S20: 0.0001 | T20: 0.17047414 | U20: 7.0922971 | V20: 1.642634 | W20: 0.47604757 | X20: 0.34404792
A21: 2. Data CS 24 AGROCAUQ estanque 68.xlsx | B21: PSO_pyswarms | C21: 200 | D21: 20 | E21: 1.5 | F21: 1.5 | G21: 0.7 | H21: 0.033679725 | I21: =3*60+53.73 -> 233.73 | J21: =I21/60 -> 3.8955 | K21: 3.8814632 | L21: 2.8667226 | M21: 6.8650101 | N21: 0.009647 | O21: 8.551854 | P21: 7.16565 | Q21: 44.15067 | R21: 42.528284 | S21: 0.0001 | T21: 1.1602649 | U21: 5.8389023 | V21: 1.642634 | W21: 0.64665747 | X21: 0.20406756
A22: 2. Data CS 24 AGROCAUQ estanque 68.xlsx | B22: PSO_pymoo | C22: 200 | D22: 20 | E22: 1.5 | F22: 1.5 | G22: 0.7 | H22: 0.0011445615 | I22: =11*60+48.17 -> 708.17 | J22: =I22/60 -> 11.802833 | K22: 0.097748778 | L22: 0.33917373 | M22: 1.7677146 | N22: 0.009647 | O22: 8.551854 | P22: 7.16565 | Q22: 44.15067 | R22: 42.528284 | S22: 0.0001 | T22: 9.9823011 | U22: 9.8388752 | V22: 1.642634 | W22: 0.14429809 | X22: 0.67235046
A23: 2. Data CS 24 AGROCAUQ estanque 68.xlsx | B23: PSO_pyswarms | C23: 500 | D23: 20 | E23: 1.5 | F23: 1.5 | G23: 0.7 | H23: 0.021153082 | I23: =11*60+34.96 -> 694.96 | J23: =I23/60 -> 11.582667 | K23: 4.6003554 | L23: 2.9392768 | M23: 1.8114258 | N23: 0.009647 | O23: 8.551854 | P23: 7.16565 | Q23: 44.15067 | R23: 42.528284 | S23: 0.0001 | T23: 2.7286635 | U23: 5.4387749 | V23: 1.642634 | W23: 0.52946081 | X23: 0.37852015
A24: 2. Data CS 24 AGROCAUQ estanque 68.xlsx | B24: PSO_pymoo | C24: 500 | D24: 20 | E24: 1.5 | F24: 1.5 | G24: 0.7 | H24: 0.001142361 | I24: =19*60+15.09 -> 1155.09 | J24: =I24/60 -> 19.2515 | K24: 0.09755629 | L24: 0.33789906 | M24: 1.7766564 | N24: 0.009647 | O24: 8.551854 | P24: 7.16565 | Q24: 44.15067 | R24: 42.528284 | S24: 0.0001 | T24: 9.9987954 | U24: 9.9698074 | V24: 1.642634 | W24: 0.14434986 | X24: 0.67196429
A25: 2. Data CS 24 AGROCAUQ estanque 68.xlsx | B25: PSO_pymoo | C25: 500 | D25: 25 | E25: 1.5 | F25: 1.5 | G25: 0.7 | H25: 0.0011658027 | I25: =30*60+57.34 -> 1857.34 | J25: =I25/60 -> 30.955667 | K25: 0.097800416 | L25: 0.71140618 | M25: 1.4257677 | N25: 0.009647 | O25: 8.551854 | P25: 7.16565 | Q25: 44.15067 | R25: 42.528284 | S25: 0.0001 | T25: 9.9977821 | U25: 6.5776873 | V25: 1.642634 | W25: 0.28729463 | X25: 0.5260588
A26: 3. Data CS 24 LOU estanque 54.xlsx | B26: PSO_gpt | C26: 150 | D26: 20 | E26: 1.5 | F26: 1.5 | G26: 0.7 | H26: 0.00053784901 | I26: =2*60+13.15 -> 133.15 | J26: =I26/60 -> 2.2191667 | K26: 0.15796536 | L26: 4.042852 | M26: 2.0987315 | N26: 0.009647 | O26: 8.551854 | P26: 7.16565 | Q26: 44.15067 | R26: 42.528284 | S26: 0.0001 | T26: 1.5329989 | U26: 0.1 | V26: 1.642634 | W26: 0.6377063 | X26: 0.25788221
A27: 3. Data CS 24 LOU estanque 54.xlsx | B27: PSO_pyswarms | C27: 150 | D27: 20 | E27: 1.5 | F27: 1.5 | G27: 0.7 | H27: 0.0041148525 | I27: =2*60+27.22 -> 147.22 | J27: =I27/60 -> 2.4536667 | K27: 2.6203393 | L27: 1.1689488 | M27: 2.7977499 | N27: 0.009647 | O27: 8.551854 | P27: 7.16565 | Q27: 44.15067 | R27: 42.528284 | S27: 0.0001 | T27: 3.6733434 | U27: 1.3912035 | V27: 1.642634 | W27: 1.0069209 | X27: 0.30911593
A28: 3. Data CS 24 LOU estanque 54.xlsx | B28: PSO_mealpy | C28: 150 | D28: 20 | E28: 1.5 | F28: 1.5 | G28: 0.7 | H28: 0.0014419232 | I28: =29*60+9.65 -> 1749.65 | J28: =I28/60 -> 29.160833 | K28: 0.4552238 | L28: 2.1090736 | M28: 0.60134453 | N28: 0.009647 | O28: 8.551854 | P28: 7.16565 | Q28: 44.15067 | R28: 42.528284 | S28: 0.0001 | T28: 3.1990571 | U28: 9.3289687 | V28: 1.642634 | W28: 0.76147207 | X28: 0.14315943
A29: 3. Data CS 24 LOU estanque 54.xlsx | B29: PSO_pymoo | C29: 150 | D29: 20 | E29: 1.5 | F29: 1.5 | G29: 0.7 | H29: 0.00055448295 | I29: =60+50.06 -> 110.06 | J29: =I29/60 -> 1.8343333 | K29: 0.18277191 | L29: 0.93507903 | M29: 5.984653 | N29: 0.009647 | O29: 8.551854 | P29: 7.16565 | Q29: 44.15067 | R29: 42.528284 | S29: 0.0001 | T29: 1.6357804 | U29: 4.4317997 | V29: 1.642634 | W29: 0.16942807 | X29: 0.79097187
A30: 3. Data CS 24 LOU estanque 54.xlsx | B30: PSO_gpt | C30: 200 | D30: 20 | E30: 1.5 | F30: 1.5 | G30: 0.7 | H30: 0.00053513471 | I30: =2*60+28.82 -> 148.82 | J30: =I30/60 -> 2.4803333 | K30: 0.15787143 | L30: 4.0399279 | M30: 2.1032253 | N30: 0.009647 | O30: 8.551854 | P30: 7.16565 | Q30: 44.15067 | R30: 42.528284 | S30: 0.0001 | T30: 1.5308576 | U30: 0.1 | V30: 1.642634 | W30: 0.63979154 | X30: 0.25571374
A31: 3. Data CS 24 LOU estanque 54.xlsx | B31: PSO_pyswarms | C31: 200 | D31: 20 | E31: 1.5 | F31: 1.5 | G31: 0.7 | H31: 0.0041059063 | I31: =2*60+58.02 -> 178.02 | J31: =I31/60 -> 2.967 | K31: 2.6203392 | L31: 1.1689508 | M31: 2.7976689 | N31: 0.009647 | O31: 8.551854 | P31: 7.16565 | Q31: 44.15067 | R31: 42.528284 | S31: 0.0001 | T31: 3.6733723 | U31: 1.3915161 | V31: 1.642634 | W31: 1.0069276 | X31: 0.3091159
A32: 3. Data CS 24 LOU estanque 54.xlsx | B32: PSO_pymoo | C32: 200 | D32: 20 | E32: 1.5 | F32: 1.5 | G32: 0.7 | H32: 0.00053926815 | I32: =2*60+31.79 -> 151.79 | J32: =I32/60 -> 2.5298333 | K32: 0.2000905 | L32: 0.93334617 | M32: 6.0599263 | N32: 0.009647 | O32: 8.551854 | P32: 7.16565 | Q32: 44.15067 | R32: 42.528284 | S32: 0.0001 | T32: 1.6315342 | U32: 3.8159681 | V32: 1.642634 | W32: 0.17471034 | X32: 0.77567939
A33: 3. Data CS 24 LOU estanque 54.xlsx | B33: PSO_gpt | C33: 500 | D33: 20 | E33: 1.5 | F33: 1.5 | G33: 0.7 | H33: 0.00052679334 | I33: =6*60+43.62 -> 403.62 | J33: =I33/60 -> 6.727 | K33: 0.15746396 | L33: 4.0531199 | M33: 2.0974793 | N33: 0.009647 | O33: 8.551854 | P33: 7.16565 | Q33: 44.15067 | R33: 42.528284 | S33: 0.0001 | T33: 1.5214141 | U33: 0.1 | V33: 1.642634 | W33: 0.64923804 | X33: 0.24784531
A34: 3. Data CS 24 LOU estanque 54.xlsx | B34: PSO_pyswarms | C34: 500 | D34: 20 | E34: 1.5 | F34: 1.5 | G34: 0.7 | H34: 0.0040861063 | I34: =60*7+58.57 -> 478.57 | J34: =I34/60 -> 7.9761667 | K34: 2.6203392 | L34: 1.1689507 | M34: 2.7976691 | N34: 0.009647 | O34: 8.551854 | P34: 7.16565 | Q34: 44.15067 | R34: 42.528284 | S34: 0.0001 | T34: 3.6733719 | U34: 1.3915183 | V34: 1.642634 | W34: 1.0069276 | X34: 0.3091159
A35: 3. Data CS 24 LOU estanque 54.xlsx | B35: PSO_pymoo | C35: 500 | D35: 20 | E35: 1.5 | F35: 1.5 | G35: 0.7 | H35: 0.00053359397 | I35: =6*60+4.39 -> 364.39 | J35: =I35/60 -> 6.0731667 | K35: 0.20078287 | L35: 0.93063361 | M35: 6.0938949 | N35: 0.009647 | O35: 8.551854 | P35: 7.16565 | Q35: 44.15067 | R35: 42.528284 | S35: 0.0001 | T35: 1.6305971 | U35: 3.9338298 | V35: 1.642634 | W35: 0.17573106 | X35: 0.76753467
A36: 3. Data CS 24 LOU estanque 54.xlsx | B36: PSO_pymoo | C36: 500 | D36: 25 | E36: 1.5 | F36: 1.5 | G36: 0.7 | H36: 0.0004996167 | I36: =10*60+4.18 -> 604.18 | J36: =I36/60 -> 10.069667 | K36: 0.1231087 | L36: 2.2809552 | M36: 9.1416504 | N36: 0.009647 | O36: 8.551854 | P36: 7.16565 | Q36: 44.15067 | R36: 42.528284 | S36: 0.0001 | T36: 0.91524578 | U36: 9.994187 | V36: 1.642634 | W36: 0.26234897 | X36: 0.6604125
A37: 4. Data CS 25 LOU estanque 31.xlsx | B37: PSO_pymoo | C37: 500 | D37: 20 | E37: 1.5 | F37: 1.5 | G37: 0.7 | H37: 0.015875439 | I37: =5*60+25.37 -> 325.37 | J37: =I37/60 -> 5.4228333 | K37: 6.8387595 | L37: 7.0477865 | M37: 4.3680299 | N37: 0.009647 | O37: 8.551854 | P37: 7.16565 | Q37: 44.15067 | R37: 42.528284 | S37: 0.0001 | T37: 0.22980742 | U37: 9.9937452 | V37: 1.642634 | W37: 0.37377443 | X37: 1.2400437
A38: 4. Data CS 25 LOU estanque 31.xlsx | B38: PSO_pymoo | C38: 500 | D38: 25 | E38: 1.5 | F38: 1.5 | G38: 0.7 | H38: 0.011921015 | I38: =3*60+53.26 -> 233.26 | J38: =I38/60 -> 3.8876667 | K38: 0.030839702 | L38: 3.6458766 | M38: 1.7015273 | N38: 0.009647 | O38: 8.551854 | P38: 7.16565 | Q38: 44.15067 | R38: 42.528284 | S38: 0.0001 | T38: 2.5919297 | U38: 5.9389336 | V38: 1.642634 | W38: 0.30809388 | X38: 1.694349
A39: 5. Data CS 24 PAROT+AURORA estanque 54.xlsx | B39: PSO_pymoo | C39: 500 | D39: 20 | E39: 1.5 | F39: 1.5 | G39: 0.7 | H39: 0.0077711676 | I39: =60*7+4.7 -> 424.7 | J39: =I39/60 -> 7.0783333 | K39: 4.1532076 | L39: 3.3138359 | M39: 9.960633 | N39: 0.009647 | O39: 8.551854 | P39: 7.16565 | Q39: 44.15067 | R39: 42.528284 | S39: 0.0001 | T39: 0.60012193 | U39: 9.9853205 | V39: 1.642634 | W39: 0.49996409 | X39: 0.78380999
A40: 5. Data CS 24 PAROT+AURORA estanque 54.xlsx | B40: PSO_pymoo | C40: 500 | D40: 25 | E40: 1.5 | F40: 1.5 | G40: 0.7 | H40: 0.0031862305 | I40: =8*60+15.77 -> 495.77 | J40: =I40/60 -> 8.2628333 | K40: 0.040770398 | L40: 2.5734116 | M40: 7.597099 | N40: 0.009647 | O40: 8.551854 | P40: 7.16565 | Q40: 44.15067 | R40: 42.528284 | S40: 0.0001 | T40: 2.2740629 | U40: 8.9849068 | V40: 1.642634 | W40: 3.9625859 | X40: 0.25923235
...

Sheet Pruebas PSO termination
A1: DE ANTES: | C1: Parámetros opt. | M1: Parámetros | AB1: Parámetros fijados
A2: Set de datos | B2: Método PSO | C2: epoch | D2: pop_size | E2: c1 | F2: c2 | G2: w | J2: Costo final opt. | K2: Tiempo (s) | L2: Tiempo (min) | M2: mu0 | N2: betaG0 | O2: betaF0 | P2: Kn0 | Q2: Kg0 | R2: Kf0 | S2: Kig0 | T2: Kie0 | U2: Kd0 | V2: Yxn | W2: Yxg | X2: Yxf | Y2: Yeg | Z2: Yef
A3: 3. Data CS 24 LOU estanque 54.xlsx | B3: PSO_pymoo | C3: 150 | D3: 20 | E3: 1.5 | F3: 1.5 | G3: 0.7 | J3: 0.00055448295 | K3: 110.06 | L3: 1.8343333 | M3: 0.18277191 | N3: 0.93507903 | O3: 5.984653 | P3: 0.009647 | Q3: 8.551854 | R3: 7.16565 | S3: 44.15067 | T3: 42.528284 | U3: 0.0001 | V3: 1.6357804 | W3: 4.4317997 | X3: 1.642634 | Y3: 0.16942807 | Z3: 0.79097187
A4: 3. Data CS 24 LOU estanque 54.xlsx | B4: PSO_pymoo | C4: 200 | D4: 20 | E4: 1.5 | F4: 1.5 | G4: 0.7 | J4: 0.00053926815 | K4: 151.79 | L4: 2.5298333 | M4: 0.2000905 | N4: 0.93334617 | O4: 6.0599263 | P4: 0.009647 | Q4: 8.551854 | R4: 7.16565 | S4: 44.15067 | T4: 42.528284 | U4: 0.0001 | V4: 1.6315342 | W4: 3.8159681 | X4: 1.642634 | Y4: 0.17471034 | Z4: 0.77567939
A5: 3. Data CS 24 LOU estanque 54.xlsx | B5: PSO_pymoo | C5: 500 | D5: 20 | E5: 1.5 | F5: 1.5 | G5: 0.7 | J5: 0.00053359397 | K5: 364.39 | L5: 6.0731667 | M5: 0.20078287 | N5: 0.93063361 | O5: 6.0938949 | P5: 0.009647 | Q5: 8.551854 | R5: 7.16565 | S5: 44.15067 | T5: 42.528284 | U5: 0.0001 | V5: 1.6305971 | W5: 3.9338298 | X5: 1.642634 | Y5: 0.17573106 | Z5: 0.76753467
A6: 3. Data CS 24 LOU estanque 54.xlsx | B6: PSO_pymoo | C6: 500 | D6: 25 | E6: 1.5 | F6: 1.5 | G6: 0.7 | J6: 0.0004996167 | K6: 604.18 | L6: 10.069667 | M6: 0.1231087 | N6: 2.2809552 | O6: 9.1416504 | P6: 0.009647 | Q6: 8.551854 | R6: 7.16565 | S6: 44.15067 | T6: 42.528284 | U6: 0.0001 | V6: 0.91524578 | W6: 9.994187 | X6: 1.642634 | Y6: 0.26234897 | Z6: 0.6604125
A7: 4. Data CS 25 LOU estanque 31.xlsx | B7: PSO_pymoo | C7: 500 | D7: 20 | E7: 1.5 | F7: 1.5 | G7: 0.7 | J7: 0.015875439 | K7: =5*60+25.37 -> 325.37 | L7: =K7/60 -> 5.4228333 | M7: 6.8387595 | N7: 7.0477865 | O7: 4.3680299 | P7: 0.009647 | Q7: 8.551854 | R7: 7.16565 | S7: 44.15067 | T7: 42.528284 | U7: 0.0001 | V7: 0.22980742 | W7: 9.9937452 | X7: 1.642634 | Y7: 0.37377443 | Z7: 1.2400437
A8: 4. Data CS 25 LOU estanque 31.xlsx | B8: PSO_pymoo | C8: 500 | D8: 25 | E8: 1.5 | F8: 1.5 | G8: 0.7 | J8: 0.011921015 | K8: =3*60+53.26 -> 233.26 | L8: =K8/60 -> 3.8876667 | M8: 0.030839702 | N8: 3.6458766 | O8: 1.7015273 | P8: 0.009647 | Q8: 8.551854 | R8: 7.16565 | S8: 44.15067 | T8: 42.528284 | U8: 0.0001 | V8: 2.5919297 | W8: 5.9389336 | X8: 1.642634 | Y8: 0.30809388 | Z8: 1.694349
A9: 5. Data CS 24 PAROT+AURORA estanque 54.xlsx | B9: PSO_pymoo | C9: 500 | D9: 20 | E9: 1.5 | F9: 1.5 | G9: 0.7 | J9: 0.0077711676 | K9: =60*7+4.7 -> 424.7 | L9: =K9/60 -> 7.0783333 | M9: 4.1532076 | N9: 3.3138359 | O9: 9.960633 | P9: 0.009647 | Q9: 8.551854 | R9: 7.16565 | S9: 44.15067 | T9: 42.528284 | U9: 0.0001 | V9: 0.60012193 | W9: 9.9853205 | X9: 1.642634 | Y9: 0.49996409 | Z9: 0.78380999
A10: 5. Data CS 24 PAROT+AURORA estanque 54.xlsx | B10: PSO_pymoo | C10: 500 | D10: 25 | E10: 1.5 | F10: 1.5 | G10: 0.7 | J10: 0.0031862305 | K10: =8*60+15.77 -> 495.77 | L10: =K10/60 -> 8.2628333 | M10: 0.040770398 | N10: 2.5734116 | O10: 7.597099 | P10: 0.009647 | Q10: 8.551854 | R10: 7.16565 | S10: 44.15067 | T10: 42.528284 | U10: 0.0001 | V10: 2.2740629 | W10: 8.9849068 | X10: 1.642634 | Y10: 3.9625859 | Z10: 0.25923235
A13: CON TERMINATION:
A14: Set de datos | B14: Método PSO | C14: epoch | D14: pop_size | E14: c1 | F14: c2 | G14: w | H14: Criterio termination | I14: Costo final opt. | J14: Tiempo (s) | K14: Tiempo (min) | L14: Iteración final | M14: mu0 | N14: betaG0 | O14: betaF0 | P14: Kn0 | Q14: Kg0 | R14: Kf0 | S14: Kig0 | T14: Kie0 | U14: Kd0 | V14: Yxn | W14: Yxg | X14: Yxf | Y14: Yeg | Z14: Yef
A15: 3. Data CS 24 LOU estanque 54.xlsx | B15: PSO_pymoo | C15: 1000 | D15: 25 | E15: 1.5 | F15: 1.5 | G15: 0.7 | H15: 0.05 | I15: 0.00055519543 | J15: =60*2+39.03 -> 159.03 | K15: =J15/60 -> 2.6505 | L15: 120 | M15: 0.17148699 | N15: 0.93708 | O15: 6.8015819 | P15: 0.009647 | Q15: 8.551854 | R15: 7.16565 | S15: 44.15067 | T15: 42.528284 | U15: 0.0001 | V15: 1.4270935 | W15: 9.4254001 | X15: 1.642634 | Y15: 0.14841027 | Z15: 0.83068676 | AA15: Se ve bastante bien, podría mejorar un poco | AE15: Probé cambiando w=0.9 pero optimiza más lento
A16: 3. Data CS 24 LOU estanque 54.xlsx | B16: PSO_pymoo | C16: 1000 | D16: 25 | E16: 1.5 | F16: 1.5 | G16: 0.7 | H16: 0.01 | I16: 0.00053728372 | J16: =3*60+57.5 -> 237.5 | K16: =J16/60 -> 3.9583333 | L16: 187 | M16: 0.17572711 | N16: 0.92101837 | O16: 7.002996 | P16: 0.009647 | Q16: 8.551854 | R16: 7.16565 | S16: 44.15067 | T16: 42.528284 | U16: 0.0001 | V16: 1.4245542 | W16: 8.4950238 | X16: 1.642634 | Y16: 0.15106342 | Z16: 0.8063665 | AA16: Bueno igual
A17: 4. Data CS 25 LOU estanque 31.xlsx | B17: PSO_pymoo | C17: 1000 | D17: 25 | E17: 1.5 | F17: 1.5 | G17: 0.7 | H17: 0.05 | I17: 0.012027692 | J17: 25.73 | K17: =J17/60 -> 0.42883333 | L17: 54 | M17: 0.030258689 | N17: 2.878001 | O17: 2.3917164 | P17: 0.009647 | Q17: 8.551854 | R17: 7.16565 | S17: 44.15067 | T17: 42.528284 | U17: 0.0001 | V17: 1.9838818 | W17: 8.1319686 | X17: 1.642634 | Y17: 0.44018479 | Z17: 2.0233553 | AA17: Bueno igual
A18: 4. Data CS 25 LOU estanque 31.xlsx | B18: PSO_pymoo | C18: 1000 | D18: 25 | E18: 1.5 | F18: 1.5 | G18: 0.7 | H18: 0.01 | I18: 0.011976392 | J18: =45.17 -> 45.17 | K18: =J18/60 -> 0.75283333 | L18: 97 | M18: 0.029339588 | N18: 2.7799338 | O18: 2.3513551 | P18: 0.009647 | Q18: 8.551854 | R18: 7.16565 | S18: 44.15067 | T18: 42.528284 | U18: 0.0001 | V18: 2.1385472 | W18: 8.4758062 | X18: 1.642634 | Y18: 0.23402858 | Z18: 2.0751152 | AA18: Bueno igual
A19: 5. Data CS 24 PAROT+AURORA estanque 54.xlsx | B19: PSO_pymoo | C19: 1000 | D19: 25 | E19: 1.5 | F19: 1.5 | G19: 0.7 | H19: 0.05 | I19: 0.003030145 | J19: =60+10.12 -> 70.12 | K19: =J19/60 -> 1.1686667 | L19: 98 | M19: 0.049273409 | N19: 2.7287439 | O19: 1.6270112 | P19: 0.009647 | Q19: 8.551854 | R19: 7.16565 | S19: 44.15067 | T19: 42.528284 | U19: 0.0001 | V19: 3.7377996 | W19: 6.2328719 | X19: 1.642634 | Y19: 0.43571283 | Z19: 2.1271801 | AA19: Bien, mejorable
A20: 5. Data CS 24 PAROT+AURORA estanque 54.xlsx | B20: PSO_pymoo | C20: 1000 | D20: 25 | E20: 1.5 | F20: 1.5 | G20: 0.7 | H20: 0.01 | I20: 0.0021315047 | J20: =60*4+6.69 -> 246.69 | K20: =J20/60 -> 4.1115 | L20: 335 | M20: 0.071260755 | N20: 1.4027474 | O20: 0.65975583 | P20: 0.009647 | Q20: 8.551854 | R20: 7.16565 | S20: 44.15067 | T20: 42.528284 | U20: 0.0001 | V20: 9.9998222 | W20: 6.7027718 | X20: 1.642634 | Y20: 0.42560517 | Z20: 2.7412488 | AA20: Buen ajuste

Sheet Pruebas variedades
A1: Set de datos (100.000 L) | B1: Método PSO | C1: Variedad | D1: Marca levadura | E1: X0 | F1: N0 | G1: G0/F0 | H1: Cantidad de datos en el perfil de azúcares | I1: epoch | J1: pop_size | K1: c1 | L1: c2 | M1: w | N1: Criterio termination | O1: Costo final opt. | P1: Tiempo (s) | Q1: Tiempo (min) | R1: Iteración de término | S1: mu0 | T1: betaG0 | U1: betaF0 | V1: Kn0 | W1: Kg0 | X1: Kf0 | Y1: Kig0 | Z1: Kie0 | AA1: Kd0 | AB1: Yxn | AC1: Yxg | AD1: Yxf | AE1: Yeg | AF1: Yef
A2: Data CS 24 EL BOLDO estanque 30.xlsx | B2: PSO_pymoo | C2: Cabernet Sauvignon | D2: IOC R 9008 | E2: 0.03703 | F2: 0.12959 | G2: 121.17482 | H2: 62 | I2: 1000 | J2: 25 | K2: 1.5 | L2: 1.5 | M2: 0.7 | N2: 0.01 | O2: 0.00091703383 | P2: =12*60+42.48 -> 762.48 | Q2: =P2/60 -> 12.708 | R2: 1001 | S2: 0.049480113 | T2: 2.8123834 | U2: 0.99007893 | V2: 0.009647 | W2: 8.551854 | X2: 7.16565 | Y2: 44.15067 | Z2: 42.528284 | AA2: 0.0001 | AB2: 6.514536 | AC2: 4.8258843 | AD2: 1.642634 | AE2: 0.17887038 | AF2: 0.96760883
A3: Data CS 24 LOU estanque 54.xlsx | B3: PSO_pymoo | C3: Cabernet Sauvignon | D3: IOC R 9008 | E3: 0.03258 | F3: 0.1412 | G3: 122.21625 | H3: 48 | I3: 1000 | J3: 25 | K3: 1.5 | L3: 1.5 | M3: 0.7 | N3: 0.01 | O3: 0.00053728372 | P3: =3*60+57.5 -> 237.5 | Q3: =P3/60 -> 3.9583333 | R3: 187 | S3: 0.17572711 | T3: 0.92101837 | U3: 7.002996 | V3: 0.009647 | W3: 8.551854 | X3: 7.16565 | Y3: 44.15067 | Z3: 42.528284 | AA3: 0.0001 | AB3: 1.4245542 | AC3: 8.4950238 | AD3: 1.642634 | AE3: 0.15106342 | AF3: 0.8063665
A4: Data CS 25 EL BOLDO estanque 55.xlsx | B4: PSO_pymoo | C4: Cabernet Sauvignon | D4: IOC R 9008 | E4: 0.0595 | F4: 0.23386 | G4: 118.59993 | H4: 47 | I4: 1000 | J4: 25 | K4: 1.5 | L4: 1.5 | M4: 0.7 | N4: 0.01 | O4: 0.0025958116 | P4: =60+20.57 -> 80.57 | Q4: =P4/60 -> 1.3428333 | R4: 160 | S4: 0.071635568 | T4: 0.33685439 | U4: 9.9287095 | V4: 0.009647 | W4: 8.551854 | X4: 7.16565 | Y4: 44.15067 | Z4: 42.528284 | AA4: 0.0001 | AB4: 2.5305362 | AC4: 5.1700246 | AD4: 1.642634 | AE4: 0.10430418 | AF4: 0.57638439 | AG4: Alcanzó el final de las iteraciones
A5: Data CS 25 LOU estanque 61.xlsx | B5: PSO_pymoo | C5: Cabernet Sauvignon | D5: IOC R 9008 | E5: 0.0579 | F5: 0.17011 | G5: 116.79993 | H5: 46 | I5: 1000 | J5: 25 | K5: 1.5 | L5: 1.5 | M5: 0.7 | N5: 0.01 | O5: 0.0012882483 | P5: =60+59.04 -> 119.04 | Q5: =P5/60 -> 1.984 | R5: 212 | S5: 0.072350666 | T5: 1.6613707 | U5: 5.2766635 | V5: 0.009647 | W5: 8.551854 | X5: 7.16565 | Y5: 44.15067 | Z5: 42.528284 | AA5: 0.0001 | AB5: 3.5667086 | AC5: 7.4683228 | AD5: 1.642634 | AE5: 0.99391512 | AF5: 0.25184996
A6: Data SY 24 LOU+VAL+FN estanque 36.xlsx | B6: PSO_pymoo | C6: Syrah | D6: IOC R 9008 | E6: 0.06291 | F6: 0.14862 | G6: 119.32777 | H6: 36 | I6: 1000 | J6: 25 | K6: 1.5 | L6: 1.5 | M6: 0.7 | N6: 0.01 | O6: 0.0005452427 | P6: =4*60+3.21 -> 243.21 | Q6: =P6/60 -> 4.0535 | R6: 308 | S6: 0.092688582 | T6: 0.82698515 | U6: 3.313003 | V6: 0.009647 | W6: 8.551854 | X6: 7.16565 | Y6: 44.15067 | Z6: 42.528284 | AA6: 0.0001 | AB6: 3.1433656 | AC6: 9.3510697 | AD6: 1.642634 | AE6: 0.21512801 | AF6: 0.58559063 | AG6: Buen ajuste
A7: Data SY 24 VAL+STARAQ estanque 56.xlsx | B7: PSO_pymoo | C7: Syrah | D7: IOC R 9008 | E7: 0.0255 | F7: 0.14379 | G7: 121.05225 | H7: 35 | I7: 1000 | J7: 25 | K7: 1.5 | L7: 1.5 | M7: 0.7 | N7: 0.01 | O7: 0.0005179416 | P7: =2*60+31.04 -> 151.04 | Q7: =P7/60 -> 2.5173333 | R7: 136 | S7: 0.18422511 | T7: 2.9503726 | U7: 2.0427887 | V7: 0.009647 | W7: 8.551854 | X7: 7.16565 | Y7: 44.15067 | Z7: 42.528284 | AA7: 0.0001 | AB7: 4.49187 | AC7: 6.9729048 | AD7: 1.642634 | AE7: 0.40447641 | AF7: 0.37700283
A8: Data SY 24 LOU estanque 62.xlsx | B8: PSO_pymoo | C8: Syrah | D8: IOC R 9008 | E8: 0.0595 | F8: 0.28657 | G8: 121.6 | H8: 40 | I8: 1000 | J8: 25 | K8: 1.5 | L8: 1.5 | M8: 0.7 | N8: 0.01 | O8: 0.0026807562 | P8: =14*60+48.75 -> 888.75 | Q8: =P8/60 -> 14.8125 | R8: 82 | S8: 0.092611655 | T8: 2.3968676 | U8: 1.0281981 | V8: 0.009647 | W8: 8.551854 | X8: 7.16565 | Y8: 44.15067 | Z8: 42.528284 | AA8: 0.0001 | AB8: 5.9702544 | AC8: 4.5947725 | AD8: 1.642634 | AE8: 0.3563308 | AF8: 0.64854763
A9: Data SY 25 LOU estanque 30.xlsx | B9: PSO_pymoo | C9: Syrah | D9: IOC R 9008 | E9: 0.05139 | F9: 0.19665 | G9: 118.81678 | H9: 35 | I9: 1000 | J9: 25 | K9: 1.5 | L9: 1.5 | M9: 0.7 | N9: 0.01 | O9: 0.0020583969 | P9: =2*60+32.66 -> 152.66 | Q9: =P9/60 -> 2.5443333 | R9: 279 | S9: 0.088806502 | T9: 3.3523979 | U9: 3.3823765 | V9: 0.009647 | W9: 8.551854 | X9: 7.16565 | Y9: 44.15067 | Z9: 42.528284 | AA9: 0.0001 | AB9: 4.6632521 | AC9: 3.3716123 | AD9: 1.642634 | AE9: 0.93668432 | AF9: 0.22641692
A10: Data ME 25 Q. AGUA estanque 85.xlsx | B10: PSO_pymoo | C10: Merlot | D10: IOC R 9008 | E10: 0.0595 | F10: 0.14987 | G10: 120.99569 | H10: 49 | I10: 1000 | J10: 25 | K10: 1.5 | L10: 1.5 | M10: 0.7 | N10: 0.01 | O10: 0.0010803961 | P10: =2*60+6.49 -> 126.49 | Q10: =P10/60 -> 2.1081667 | R10: 305 | S10: 0.028278904 | T10: 2.38405 | U10: 4.4014286 | V10: 0.009647 | W10: 8.551854 | X10: 7.16565 | Y10: 44.15067 | Z10: 42.528284 | AA10: 0.0001 | AB10: 1.8014323 | AC10: 4.5414411 | AD10: 1.642634 | AE10: 0.51124239 | AF10: 0.29495795
A11: Data ME 24 QAGUA estanque 54.xlsx | B11: PSO_pymoo | C11: Merlot | D11: IOC R 9008 | E11: 0.03853 | F11: 0.14248 | G11: 121 | H11: 41 | I11: 1000 | J11: 25 | K11: 1.5 | L11: 1.5 | M11: 0.7 | N11: 0.01 | O11: 0.00043972553 | P11: =60+40.41 -> 100.41 | Q11: =P11/60 -> 1.6735 | R11: 128 | S11: 0.092203785 | T11: 2.6433716 | U11: 0.6685867 | V11: 0.009647 | W11: 8.551854 | X11: 7.16565 | Y11: 44.15067 | Z11: 42.528284 | AA11: 0.0001 | AB11: 4.1989298 | AC11: 6.0398716 | AD11: 1.642634 | AE11: 0.51999972 | AF11: 0.16439565
A12: Data ME 25 AURORA + STA MARTA estanque 57.xlsx | B12: PSO_pymoo | C12: Merlot | D12: IOC R 9008 | E12: 0.0595 | F12: 0.1497 | G12: 121.38906 | H12: 52 | I12: 1000 | J12: 25 | K12: 1.5 | L12: 1.5 | M12: 0.7 | N12: 0.01 | O12: 0.0012485476 | P12: =60+2.87 -> 62.87 | Q12: =P12/60 -> 1.0478333 | R12: 131 | S12: 0.029631189 | T12: 1.14072 | U12: 10 | V12: 0.009647 | W12: 8.551854 | X12: 7.16565 | Y12: 44.15067 | Z12: 42.528284 | AA12: 0.0001 | AB12: 0.96881493 | AC12: 8.9496248 | AD12: 1.642634 | AE12: 0.10000481 | AF12: 0.80615988
A13: Data ME 25 STA MARTA estanque 62.xlsx | B13: PSO_pymoo | C13: Merlot | D13: Siembra | E13: 0.2 | F13: 0.15121 | G13: 121.10926 | H13: 35 | I13: 1000 | J13: 25 | K13: 1.5 | L13: 1.5 | M13: 0.7 | N13: 0.01 | O13: 0.0032809641 | P13: 42 | Q13: =P13/60 -> 0.7 | R13: 75 | S13: 0.040822695 | T13: 3.9857932 | U13: 5.4224425 | V13: 0.009647 | W13: 8.551854 | X13: 7.16565 | Y13: 44.15067 | Z13: 42.528284 | AA13: 0.0001 | AB13: 0.11828668 | AC13: 6.1500928 | AD13: 1.642634 | AE13: 0.2450839 | AF13: 0.71906851
A14: Data CA 24 VAL estanque 31.xlsx | B14: PSO_pymoo | C14: Carmenere | D14: IOC R 9008 | E14: 0.07323 | F14: 0.07883 | G14: 121.0861 | H14: 53 | I14: 1000 | J14: 25 | K14: 1.5 | L14: 1.5 | M14: 0.7 | N14: 0.01 | O14: 0.0014649932 | P14: =2*60+22.57 -> 142.57 | Q14: =P14/60 -> 2.3761667 | R14: 152 | S14: 0.092110416 | T14: 3.7385119 | U14: 1.0572669 | V14: 0.009647 | W14: 8.551854 | X14: 7.16565 | Y14: 44.15067 | Z14: 42.528284 | AA14: 0.0001 | AB14: 4.4737865 | AC14: 9.7209061 | AD14: 1.642634 | AE14: 0.60032924 | AF14: 0.17328355
A15: Data CA 24 VAL estanque 59.xlsx | B15: PSO_pymoo | C15: Carmenere | D15: IOC R 9008 | E15: 0.08289 | F15: 0.13661 | G15: 121.37479 | H15: 47 | I15: 1000 | J15: 25 | K15: 1.5 | L15: 1.5 | M15: 0.7 | N15: 0.01 | O15: 0.0029740324 | P15: =6*60+33.59 -> 393.59 | Q15: =P15/60 -> 6.5598333 | R15: 430 | S15: 0.084825421 | T15: 0.48818173 | U15: 1.4308126 | V15: 0.009647 | W15: 8.551854 | X15: 7.16565 | Y15: 44.15067 | Z15: 42.528284 | AA15: 0.0001 | AB15: 9.9990892 | AC15: 7.4850888 | AD15: 1.642634 | AE15: 0.44781588 | AF15: 0.31687109
A16: Data CA 24 VAL estanque 62.xlsx | B16: PSO_pymoo | C16: Carmenere | D16: IOC R 9008 | E16: 0.07303 | F16: 0.13259 | G16: 121.85446 | H16: 64 | I16: 1000 | J16: 25 | K16: 1.5 | L16: 1.5 | M16: 0.7 | N16: 0.01 | O16: 0.0034661452 | P16: 47.79 | Q16: =P16/60 -> 0.7965 | R16: 103 | S16: 0.02668177 | T16: 0.86784841 | U16: 3.1751499 | V16: 0.009647 | W16: 8.551854 | X16: 7.16565 | Y16: 44.15067 | Z16: 42.528284 | AA16: 0.0001 | AB16: 4.583478 | AC16: 8.789637 | AD16: 1.642634 | AE16: 0.1046245 | AF16: 0.6030284
A17: Data CA 25 F.N. estanque 68.xlsx | B17: PSO_pymoo | C17: Carmenere | D17: IOC R 9008 | E17: 0.0595 | F17: 0.14533 | G17: 121.0857 | H17: 54 | I17: 1000 | J17: 25 | K17: 1.5 | L17: 1.5 | M17: 0.7 | N17: 0.01 | O17: 0.0007226157 | P17: =60+5.13 -> 65.13 | Q17: =P17/60 -> 1.0855 | R17: 123 | S17: 0.052129883 | T17: 6.400139 | U17: 2.7768277 | V17: 0.009647 | W17: 8.551854 | X17: 7.16565 | Y17: 44.15067 | Z17: 42.528284 | AA17: 0.0001 | AB17: 1.7419491 | AC17: 3.1982747 | AD17: 1.642634 | AE17: 0.7281857 | AF17: 0.19993265
H20: =SUM(H2:H5) -> 203 | R20: Promedio CS | S20: =AVERAGE(S2:S5) -> 0.092298364 | T20: =AVERAGE(T2:T5) -> 1.4329067 | U20: =AVERAGE(U2:U5) -> 5.799612 | AB20: =AVERAGE(AB2:AB5) -> 3.5090838 | AC20: =AVERAGE(AC2:AC5) -> 6.4898139 | AE20: =AVERAGE(AE2:AE5) -> 0.35703828 | AF20: =AVERAGE(AF2:AF5) -> 0.65055242
R21: Desv. Est. CS | S21: =_xlfn.STDEV.S(S2:S5) -> 0.056623375 | T21: =_xlfn.STDEV.S(T2:T5) -> 1.0674755 | U21: =_xlfn.STDEV.S(U2:U5) -> 3.7373191 | AB21: =_xlfn.STDEV.S(AB2:AB5) -> 2.1862359 | AC21: =_xlfn.STDEV.S(AC2:AC5) -> 1.7784686 | AE21: =_xlfn.STDEV.S(AE2:AE5) -> 0.42569789 | AF21: =_xlfn.STDEV.S(AF2:AF5) -> 0.31051964
H22: =SUM(H6:H9) -> 146 | R22: Promedio SY | S22: =AVERAGE(S6:S9) -> 0.11458296 | T22: =AVERAGE(T6:T9) -> 2.3816558 | U22: =AVERAGE(U6:U9) -> 2.4415916 | AB22: =AVERAGE(AB6:AB9) -> 4.5671855 | AC22: =AVERAGE(AC6:AC9) -> 6.0725899 | AE22: =AVERAGE(AE6:AE9) -> 0.47815489 | AF22: =AVERAGE(AF6:AF9) -> 0.4593895
R23: Desv. Est. SY | S23: =_xlfn.STDEV.S(S6:S9) -> 0.046463449 | T23: =_xlfn.STDEV.S(T6:T9) -> 1.1080029 | U23: =_xlfn.STDEV.S(U6:U9) -> 1.1256345 | AB23: =_xlfn.STDEV.S(AB6:AB9) -> 1.1562535 | AC23: =_xlfn.STDEV.S(AC6:AC9) -> 2.6481579 | AE23: =_xlfn.STDEV.S(AE6:AE9) -> 0.31607067 | AF23: =_xlfn.STDEV.S(AF6:AF9) -> 0.19388253
H24: =SUM(H10:H13) -> 177 | R24: Promedio ME | S24: =AVERAGE(S10:S13) -> 0.047734143 | T24: =AVERAGE(T10:T13) -> 2.5384837 | U24: =AVERAGE(U10:U13) -> 5.1231144 | AB24: =AVERAGE(AB10:AB13) -> 1.771866 | AC24: =AVERAGE(AC10:AC13) -> 6.4202576 | AE24: =AVERAGE(AE10:AE13) -> 0.3440827 | AF24: =AVERAGE(AF10:AF13) -> 0.4961455
R25: Desv. Est. ME | S25: =_xlfn.STDEV.S(S10:S13) -> 0.030174716 | T25: =_xlfn.STDEV.S(T10:T13) -> 1.1666618 | U25: =_xlfn.STDEV.S(U10:U13) -> 3.8400199 | AB25: =_xlfn.STDEV.S(AB10:AB13) -> 1.7579087 | AC25: =_xlfn.STDEV.S(AC10:AC13) -> 1.838961 | AE25: =_xlfn.STDEV.S(AE10:AE13) -> 0.20677196 | AF25: =_xlfn.STDEV.S(AF10:AF13) -> 0.31429178
H26: =SUM(H14:H17) -> 218 | R26: Promedio CA | S26: =AVERAGE(S14:S17) -> 0.063936873 | T26: =AVERAGE(T14:T17) -> 2.8736702 | U26: =AVERAGE(U14:U17) -> 2.1100143 | AB26: =AVERAGE(AB14:AB17) -> 5.1995757 | AC26: =AVERAGE(AC14:AC17) -> 7.2984767 | AE26: =AVERAGE(AE14:AE17) -> 0.47023883 | AF26: =AVERAGE(AF14:AF17) -> 0.32327892
R27: Desv. Est. CA | S27: =_xlfn.STDEV.S(S14:S17) -> 0.030317364 | T27: =_xlfn.STDEV.S(T14:T17) -> 2.7627166 | U27: =_xlfn.STDEV.S(U14:U17) -> 1.0244911 | AB27: =_xlfn.STDEV.S(AB14:AB17) -> 3.4591356 | AC27: =_xlfn.STDEV.S(AC14:AC17) -> 2.8831813 | AE27: =_xlfn.STDEV.S(AE14:AE17) -> 0.26934286 | AF27: =_xlfn.STDEV.S(AF14:AF17) -> 0.19665007
R29: Promedio tot | S29: =AVERAGE(S2:S17) -> 0.079638085 | T29: =AVERAGE(T2:T17) -> 2.3066791 | U29: =AVERAGE(U2:U17) -> 3.8685831 | AB29: =AVERAGE(AB2:AB17) -> 3.7619277 | AC29: =AVERAGE(AC2:AC17) -> 6.5702845 | AE29: =AVERAGE(AE2:AE17) -> 0.41237867 | AF29: =AVERAGE(AF2:AF17) -> 0.48234159
R30: Desv. Est. Tot | S30: =_xlfn.STDEV.S(S2:S17) -> 0.046308682 | T30: =_xlfn.STDEV.S(T2:T17) -> 1.605405 | U30: =_xlfn.STDEV.S(U2:U17) -> 2.997957 | AB30: =_xlfn.STDEV.S(AB2:AB17) -> 2.455951 | AC30: =_xlfn.STDEV.S(AC2:AC17) -> 2.142248 | AE30: =_xlfn.STDEV.S(AE2:AE17) -> 0.28877483 | AF30: =_xlfn.STDEV.S(AF2:AF17) -> 0.26225217
A32: ESTIMACIÓN 100.000 L CON LOS 4 SETS DE DATOS
A33: Set de datos (100.000 L) | B33: Método PSO | C33: Variedad | D33: Marca levadura | I33: epoch | J33: pop_size | K33: c1 | L33: c2 | M33: w | N33: Criterio termination | O33: Costo final opt. | P33: Tiempo (s) | Q33: Tiempo (min) | R33: Iteración de término | S33: mu0 | T33: betaG0 | U33: betaF0 | V33: Kn0 | W33: Kg0 | X33: Kf0 | Y33: Kig0 | Z33: Kie0 | AA33: Kd0 | AB33: Yxn | AC33: Yxg | AD33: Yxf | AE33: Yeg | AF33: Yef
A34: - | B34: PSO_pymoo | C34: Cabernet Sauvignon | D34: - | I34: 1000 | J34: 25 | K34: 1.5 | L34: 1.5 | M34: 0.7 | N34: 0.01 | O34: 0.044323896 | P34: =18*60+32.02 -> 1112.02 | Q34: =P34/60 -> 18.533667 | R34: 319 | S34: 0.067194505 | T34: 3.5852077 | U34: 2.5841699 | V34: 0.009647 | W34: 8.551854 | X34: 7.16565 | Y34: 44.15067 | Z34: 42.528284 | AA34: 0.0001 | AB34: 1.5522365 | AC34: 3.1992792 | AD34: 1.642634 | AE34: 0.99509344 | AF34: 0.11123297 | AG34: Bueno para los sets, no perfecto
A35: - | B35: PSO_pymoo | C35: Syrah | D35: - | I35: 1000 | J35: 25 | K35: 1.5 | L35: 1.5 | M35: 0.7 | N35: 0.01 | O35: 0.10948936 | P35: =116*60+28.63 -> 6988.63 | Q35: =P35/60 -> 116.47717 | R35: 250 | S35: 0.10971087 | T35: 4.3921531 | U35: 0.66659481 | V35: 0.009647 | W35: 8.551854 | X35: 7.16565 | Y35: 44.15067 | Z35: 42.528284 | AA35: 0.0001 | AB35: 4.6756525 | AC35: 4.969968 | AD35: 1.642634 | AE35: 0.6221363 | AF35: 0.21172106 | AG35: No muy bueno
A36: - | B36: PSO_pymoo | C36: Merlot | D36: - | I36: 1000 | J36: 25 | K36: 1.5 | L36: 1.5 | M36: 0.7 | N36: 0.01 | O36: 0.052039279 | P36: =9*60+59.45 -> 599.45 | Q36: =P36/60 -> 9.9908333 | R36: 143 | S36: 0.093049521 | T36: 2.0666549 | U36: 0.97768888 | V36: 0.009647 | W36: 8.551854 | X36: 7.16565 | Y36: 44.15067 | Z36: 42.528284 | AA36: 0.0001 | AB36: 4.2720681 | AC36: 3.5218613 | AD36: 1.642634 | AE36: 0.42123755 | AF36: 0.41577529 | AG36: Relativamente bueno (excepto el primero)
A37: - | B37: PSO_pymoo | C37: Carmenere | D37: - | I37: 1000 | J37: 25 | K37: 1.5 | L37: 1.5 | M37: 0.7 | N37: 0.01 | V37: 0.009647 | W37: 8.551854 | X37: 7.16565 | Y37: 44.15067 | Z37: 42.528284 | AA37: 0.0001 | AD37: 1.642634
A41: Set de datos (80.000 L) | B41: Método PSO | C41: Variedad | D41: Marca levadura | E41: X0 | F41: N0 | G41: G0/F0 | H41: Cantidad de datos en el perfil de azúcares | I41: epoch | J41: pop_size | K41: c1 | L41: c2 | M41: w | N41: Criterio termination | O41: Costo final opt. | P41: Tiempo (s) | Q41: Tiempo (min) | R41: Iteración de término | S41: mu0 | T41: betaG0 | U41: betaF0 | V41: Kn0 | W41: Kg0 | X41: Kf0 | Y41: Kig0 | Z41: Kie0 | AA41: Kd0 | AB41: Yxn | AC41: Yxg | AD41: Yxf | AE41: Yeg | AF41: Yef
A42: Data CS 25 BOLDO + STA MARTA estanque 41.xlsx | B42: PSO_pymoo | C42: Cabernet Sauvignon | D42: IOC R 9008 | E42: 0.0595 | F42: 0.13804 | G42: 121.6 | H42: 48 | I42: 1000 | J42: 25 | K42: 1.5 | L42: 1.5 | M42: 0.7 | N42: 0.01 | O42: 0.0018381289 | P42: =2*60+8.54 -> 128.54 | Q42: =P42/60 -> 2.1423333 | R42: 202 | S42: 0.063637804 | T42: 1.5582451 | U42: 4.3183362 | V42: 0.009647 | W42: 8.551854 | X42: 7.16565 | Y42: 44.15067 | Z42: 42.528284 | AA42: 0.0001 | AB42: 2.6711944 | AC42: 8.0181132 | AD42: 1.642634 | AE42: 0.25945086 | AF42: 0.40289323
A43: Data CS 25 EL BOLDO (C88 - 89) estanque 50.xlsx | B43: PSO_pymoo | C43: Cabernet Sauvignon | D43: IOC R 9008 | E43: 0.0595 | F43: 0.14081 | G43: 121.17343 | H43: 42 | I43: 1000 | J43: 25 | K43: 1.5 | L43: 1.5 | M43: 0.7 | N43: 0.01 | O43: 0.001079824 | P43: =8*60+35.86 -> 515.86 | Q43: =P43/60 -> 8.5976667 | R43: 86 | S43: 0.23758341 | T43: 3.5472371 | U43: 2.3849268 | V43: 0.009647 | W43: 8.551854 | X43: 7.16565 | Y43: 44.15067 | Z43: 42.528284 | AA43: 0.0001 | AB43: 2.0984518 | AC43: 1.1374318 | AD43: 1.642634 | AE43: 0.34943006 | AF43: 0.4831809
A44: Data CS+MA 24 COL+JMU+IVALDES estanque 41.xlsx | B44: PSO_pymoo | C44: Cabernet Sauvignon | D44: IOC R 9008 | E44: 0.14832 | F44: 0.13338 | G44: 122.06081 | H44: 33 | I44: 1000 | J44: 25 | K44: 1.5 | L44: 1.5 | M44: 0.7 | N44: 0.01 | O44: 0.0010881467 | P44: =7*60+55.85 -> 475.85 | Q44: =P44/60 -> 7.9308333 | R44: 283 | S44: 0.094936012 | T44: 4.9276954 | U44: 1.6220267 | V44: 0.009647 | W44: 8.551854 | X44: 7.16565 | Y44: 44.15067 | Z44: 42.528284 | AA44: 0.0001 | AB44: 2.8194967 | AC44: 8.9133348 | AD44: 1.642634 | AE44: 0.39788094 | AF44: 0.56462336
A45: Data CA 25 VAL estanque 38.xlsx | B45: PSO_pymoo | C45: Carmenere | D45: IOC R 9008 | E45: 0.0595 | F45: 0.1387 | G45: 121.08707 | H45: 56 | I45: 1000 | J45: 25 | K45: 1.5 | L45: 1.5 | M45: 0.7 | N45: 0.01 | O45: 0.0384023 | P45: =60+30.08 -> 90.08 | Q45: =P45/60 -> 1.5013333 | R45: 178 | S45: 0.0384023 | T45: 2.1158006 | U45: 5.4999272 | V45: 0.009647 | W45: 8.551854 | X45: 7.16565 | Y45: 44.15067 | Z45: 42.528284 | AA45: 0.0001 | AB45: 1.8579909 | AC45: 8.1775317 | AD45: 1.642634 | AE45: 0.31757632 | AF45: 0.54477961
A46: Data ME 24 QAGUA estanque 48.xlsx | B46: PSO_pymoo | C46: Merlot | D46: IOC R 9008 | E46: 0.0208 | F46: 0.13407 | G46: 112 | H46: 47 | I46: 1000 | J46: 25 | K46: 1.5 | L46: 1.5 | M46: 0.7 | N46: 0.01 | O46: 0.0088265948 | P46: =60+43.74 -> 103.74 | Q46: =P46/60 -> 1.729 | R46: 89 | S46: 0.10538345 | T46: 3.5356768 | U46: 9.9829332 | V46: 0.009647 | W46: 8.551854 | X46: 7.16565 | Y46: 44.15067 | Z46: 42.528284 | AA46: 0.0001 | AB46: 1.1756748 | AC46: 9.2070072 | AD46: 1.642634 | AE46: 0.52073472 | AF46: 0.44949092
A47: Data ME 25 Q. AGUA estanque 40.xlsx | B47: PSO_pymoo | C47: Merlot | D47: IOC R 9008 | E47: 0.0595 | F47: 0.14667 | G47: 122.27418 | H47: 38 | I47: 1000 | J47: 25 | K47: 1.5 | L47: 1.5 | M47: 0.7 | N47: 0.01 | O47: 0.00048442652 | P47: =2*60+3.13 -> 123.13 | Q47: =P47/60 -> 2.0521667 | R47: 217 | S47: 0.048741437 | T47: 7.6603532 | U47: 1.5229206 | V47: 0.009647 | W47: 8.551854 | X47: 7.16565 | Y47: 44.15067 | Z47: 42.528284 | AA47: 0.0001 | AB47: 3.9188958 | AC47: 6.0185853 | AD47: 1.642634 | AE47: 0.31333773 | AF47: 0.44569093
...

Sheet Análisis estadístico variedades
L1: N° params | M1: 7
C2: mu0 | D2: betaG0 | E2: betaF0 | F2: Yxn | G2: Yxg | H2: Yeg | I2: Yef | J2: N de datos | K2: N fermentaciones | L2: dfi
B3: Promedio CS | C3: ='Pruebas variedades'!S20 -> 0.092298364 | D3: ='Pruebas variedades'!T20 -> 1.4329067 | E3: ='Pruebas variedades'!U20 -> 5.799612 | F3: ='Pruebas variedades'!AB20 -> 3.5090838 | G3: ='Pruebas variedades'!AC20 -> 6.4898139 | H3: ='Pruebas variedades'!AE20 -> 0.35703828 | I3: ='Pruebas variedades'!AF20 -> 0.65055242 | J3: =SUM('Pruebas variedades'!H2:H5)+4 -> 207 | K3: 4 | L3: =J3-$M$1 -> 200
B4: Desv. Est. CS | C4: ='Pruebas variedades'!S21 -> 0.056623375 | D4: ='Pruebas variedades'!T21 -> 1.0674755 | E4: ='Pruebas variedades'!U21 -> 3.7373191 | F4: ='Pruebas variedades'!AB21 -> 2.1862359 | G4: ='Pruebas variedades'!AC21 -> 1.7784686 | H4: ='Pruebas variedades'!AE21 -> 0.42569789 | I4: ='Pruebas variedades'!AF21 -> 0.31051964
B5: Promedio SY | C5: ='Pruebas variedades'!S22 -> 0.11458296 | D5: ='Pruebas variedades'!T22 -> 2.3816558 | E5: ='Pruebas variedades'!U22 -> 2.4415916 | F5: ='Pruebas variedades'!AB22 -> 4.5671855 | G5: ='Pruebas variedades'!AC22 -> 6.0725899 | H5: ='Pruebas variedades'!AE22 -> 0.47815489 | I5: ='Pruebas variedades'!AF22 -> 0.4593895 | J5: =SUM('Pruebas variedades'!H6:H9)+4 -> 150 | K5: 4 | L5: =J5-$M$1 -> 143
B6: Desv. Est. SY | C6: ='Pruebas variedades'!S23 -> 0.046463449 | D6: ='Pruebas variedades'!T23 -> 1.1080029 | E6: ='Pruebas variedades'!U23 -> 1.1256345 | F6: ='Pruebas variedades'!AB23 -> 1.1562535 | G6: ='Pruebas variedades'!AC23 -> 2.6481579 | H6: ='Pruebas variedades'!AE23 -> 0.31607067 | I6: ='Pruebas variedades'!AF23 -> 0.19388253
B7: Promedio ME | C7: ='Pruebas variedades'!S24 -> 0.047734143 | D7: ='Pruebas variedades'!T24 -> 2.5384837 | E7: ='Pruebas variedades'!U24 -> 5.1231144 | F7: ='Pruebas variedades'!AB24 -> 1.771866 | G7: ='Pruebas variedades'!AC24 -> 6.4202576 | H7: ='Pruebas variedades'!AE24 -> 0.3440827 | I7: ='Pruebas variedades'!AF24 -> 0.4961455 | J7: =SUM('Pruebas variedades'!H10:H13)+4 -> 181 | K7: 4 | L7: =J7-$M$1 -> 174
B8: Desv. Est. ME | C8: ='Pruebas variedades'!S25 -> 0.030174716 | D8: ='Pruebas variedades'!T25 -> 1.1666618 | E8: ='Pruebas variedades'!U25 -> 3.8400199 | F8: ='Pruebas variedades'!AB25 -> 1.7579087 | G8: ='Pruebas variedades'!AC25 -> 1.838961 | H8: ='Pruebas variedades'!AE25 -> 0.20677196 | I8: ='Pruebas variedades'!AF25 -> 0.31429178
B9: Promedio CA | C9: ='Pruebas variedades'!S26 -> 0.063936873 | D9: ='Pruebas variedades'!T26 -> 2.8736702 | E9: ='Pruebas variedades'!U26 -> 2.1100143 | F9: ='Pruebas variedades'!AB26 -> 5.1995757 | G9: ='Pruebas variedades'!AC26 -> 7.2984767 | H9: ='Pruebas variedades'!AE26 -> 0.47023883 | I9: ='Pruebas variedades'!AF26 -> 0.32327892 | J9: =SUM('Pruebas variedades'!H14:H17)+4 -> 222 | K9: 4 | L9: =J9-$M$1 -> 215
B10: Desv. Est. CA | C10: ='Pruebas variedades'!S27 -> 0.030317364 | D10: ='Pruebas variedades'!T27 -> 2.7627166 | E10: ='Pruebas variedades'!U27 -> 1.0244911 | F10: ='Pruebas variedades'!AB27 -> 3.4591356 | G10: ='Pruebas variedades'!AC27 -> 2.8831813 | H10: ='Pruebas variedades'!AE27 -> 0.26934286 | I10: ='Pruebas variedades'!AF27 -> 0.19665007
C14: mu0 | D14: betaG0 | E14: betaF0 | F14: Yxn | G14: Yxg | H14: Yeg | I14: Yef
A15: t | B15: CS-SY | C15: =(C3-C5)/(SQRT(C4^2+C6^2)) -> -0.30424087 | D15: =(D3-D5)/(SQRT(D4^2+D6^2)) -> -0.61664645 | E15: =(E3-E5)/(SQRT(E4^2+E6^2)) -> 0.86033523 | F15: =(F3-F5)/(SQRT(F4^2+F6^2)) -> -0.42783291 | G15: =(G3-G5)/(SQRT(G4^2+G6^2)) -> 0.13079386 | H15: =(H3-H5)/(SQRT(H4^2+H6^2)) -> -0.22843273 | I15: =(I3-I5)/(SQRT(I4^2+I6^2)) -> 0.52219219
B16: CS-ME | C16: =(C3-C7)/(SQRT(C4^2+C8^2)) -> 0.69456141 | D16: =(D3-D7)/(SQRT(D4^2+D8^2)) -> -0.69914384 | E16: =(E3-E7)/(SQRT(E4^2+E8^2)) -> 0.12624803 | F16: =(F3-F7)/(SQRT(F4^2+F8^2)) -> 0.61925637 | G16: =(G3-G7)/(SQRT(G4^2+G8^2)) -> 0.027188837 | H16: =(H3-H7)/(SQRT(H4^2+H8^2)) -> 0.027375276 | I16: =(I3-I7)/(SQRT(I4^2+I8^2)) -> 0.34948206
B17: CS-CA | C17: =(C3-C9)/(SQRT(C4^2+C10^2)) -> 0.44156913 | D17: =(D3-D9)/(SQRT(D4^2+D10^2)) -> -0.48645284 | E17: =(E3-E9)/(SQRT(E4^2+E10^2)) -> 0.95210634 | F17: =(F3-F9)/(SQRT(F4^2+F10^2)) -> -0.41311153 | G17: =(G3-G9)/(SQRT(G4^2+G10^2)) -> -0.23871415 | H17: =(H3-H9)/(SQRT(H4^2+H10^2)) -> -0.22471565 | I17: =(I3-I9)/(SQRT(I4^2+I10^2)) -> 0.8904167
B18: SY-ME | C18: =(C7-C5)/(SQRT(C8^2+C6^2)) -> -1.206617 | D18: =(D7-D5)/(SQRT(D8^2+D6^2)) -> 0.097471245 | E18: =(E7-E5)/(SQRT(E8^2+E6^2)) -> 0.67011261 | F18: =(F7-F5)/(SQRT(F8^2+F6^2)) -> -1.3285216 | G18: =(G7-G5)/(SQRT(G8^2+G6^2)) -> 0.10783561 | H18: =(H7-H5)/(SQRT(H8^2+H6^2)) -> -0.3549725 | I18: =(I7-I5)/(SQRT(I8^2+I6^2)) -> 0.099533473
B19: SY-CA | C19: =(C9-C5)/(SQRT(C10^2+C6^2)) -> -0.9128764 | D19: =(D9-D5)/(SQRT(D10^2+D6^2)) -> 0.16529293 | E19: =(E9-E5)/(SQRT(E10^2+E6^2)) -> -0.21784921 | F19: =(F9-F5)/(SQRT(F10^2+F6^2)) -> 0.1733875 | G19: =(G9-G5)/(SQRT(G10^2+G6^2)) -> 0.3131435 | H19: =(H9-H5)/(SQRT(H10^2+H6^2)) -> -0.019062592 | I19: =(I9-I5)/(SQRT(I10^2+I6^2)) -> -0.49287716
B20: ME-CA | C20: =(C9-C7)/(SQRT(C10^2+C8^2)) -> 0.37879432 | D20: =(D9-D7)/(SQRT(D10^2+D8^2)) -> 0.11176796 | E20: =(E9-E7)/(SQRT(E10^2+E8^2)) -> -0.75813956 | F20: =(F9-F7)/(SQRT(F10^2+F8^2)) -> 0.88338744 | G20: =(G9-G7)/(SQRT(G10^2+G8^2)) -> 0.25680994 | H20: =(H9-H7)/(SQRT(H10^2+H8^2)) -> 0.37152948 | I20: =(I9-I7)/(SQRT(I10^2+I8^2)) -> -0.4662703
A21: df | B21: CS-SY | C21: =(C4^2+C6^2)^2/(C4^4/$L$3+C6^4/$L$5) -> 342.70285 | D21: =(D4^2+D6^2)^2/(D4^4/$L$3+D6^4/$L$5) -> 328.99865 | E21: =(E4^2+E6^2)^2/(E4^4/$L$3+E6^4/$L$5) -> 235.22419 | F21: =(F4^2+F6^2)^2/(F4^4/$L$3+F6^4/$L$5) -> 295.2275 | G21: =(G4^2+G6^2)^2/(G4^4/$L$3+G6^4/$L$5) -> 262.85243 | H21: =(H4^2+H6^2)^2/(H4^4/$L$3+H6^4/$L$5) -> 337.73804 | I21: =(I4^2+I6^2)^2/(I4^4/$L$3+I6^4/$L$5) -> 318.61165
B22: CS-ME | C22: =(C4^2+C8^2)^2/(C4^4/$L$3+C8^4/$L$7) -> 301.75155 | D22: =(D4^2+D8^2)^2/(D4^4/$L$3+D8^4/$L$7) -> 364.83238 | E22: =(E4^2+E8^2)^2/(E4^4/$L$3+E8^4/$L$7) -> 370.52412 | F22: =(F4^2+F8^2)^2/(F4^4/$L$3+F8^4/$L$7) -> 366.24666 | G22: =(G4^2+G8^2)^2/(G4^4/$L$3+G8^4/$L$7) -> 370.05848 | H22: =(H4^2+H8^2)^2/(H4^4/$L$3+H8^4/$L$7) -> 287.13317 | I22: =(I4^2+I8^2)^2/(I4^4/$L$3+I8^4/$L$7) -> 371.51467
B23: CS-CA | C23: =(C4^2+C10^2)^2/(C4^4/$L$3+C10^4/$L$9) -> 307.59182 | D23: =(D4^2+D10^2)^2/(D4^4/$L$3+D10^4/$L$9) -> 277.34336 | E23: =(E4^2+E10^2)^2/(E4^4/$L$3+E10^4/$L$9) -> 229.97904 | F23: =(F4^2+F10^2)^2/(F4^4/$L$3+F10^4/$L$9) -> 359.418 | G23: =(G4^2+G10^2)^2/(G4^4/$L$3+G10^4/$L$9) -> 354.55813 | H23: =(H4^2+H10^2)^2/(H4^4/$L$3+H10^4/$L$9) -> 341.29996 | I23: =(I4^2+I10^2)^2/(I4^4/$L$3+I10^4/$L$9) -> 341.49684
B24: SY-ME | C24: =(C8^2+C6^2)^2/(C8^4/$L$7+C6^4/$L$5) -> 252.19204 | D24: =(D8^2+D6^2)^2/(D8^4/$L$7+D6^4/$L$5) -> 316.31684 | E24: =(E8^2+E6^2)^2/(E8^4/$L$7+E6^4/$L$5) -> 203.36019 | F24: =(F8^2+F6^2)^2/(F8^4/$L$7+F6^4/$L$5) -> 290.87666 | G24: =(G8^2+G6^2)^2/(G8^4/$L$7+G6^4/$L$5) -> 263.76336 | H24: =(H8^2+H6^2)^2/(H8^4/$L$7+H6^4/$L$5) -> 253.44169 | I24: =(I8^2+I6^2)^2/(I8^4/$L$7+I6^4/$L$5) -> 281.9471
B25: SY-CA | C25: =(C10^2+C6^2)^2/(C10^4/$L$9+C6^4/$L$5) -> 259.41156 | D25: =(D10^2+D6^2)^2/(D10^4/$L$9+D6^4/$L$5) -> 278.87828 | E25: =(E10^2+E6^2)^2/(E10^4/$L$9+E6^4/$L$5) -> 328.23325 | F25: =(F10^2+F6^2)^2/(F10^4/$L$9+F6^4/$L$5) -> 260.83242 | G25: =(G10^2+G6^2)^2/(G10^4/$L$9+G6^4/$L$5) -> 353.02454 | H25: =(H10^2+H6^2)^2/(H10^4/$L$9+H6^4/$L$5) -> 315.45372 | I25: =(I10^2+I6^2)^2/(I10^4/$L$9+I6^4/$L$5) -> 345.41928
B26: ME-CA | C26: =(C10^2+C8^2)^2/(C10^4/$L$9+C8^4/$L$7) -> 385.05291 | D26: =(D10^2+D8^2)^2/(D10^4/$L$9+D8^4/$L$7) -> 287.23136 | E26: =(E10^2+E8^2)^2/(E10^4/$L$9+E8^4/$L$7) -> 198.83643 | F26: =(F10^2+F8^2)^2/(F10^4/$L$9+F8^4/$L$7) -> 314.47471 | G26: =(G10^2+G8^2)^2/(G10^4/$L$9+G8^4/$L$7) -> 353.2713 | H26: =(H10^2+H8^2)^2/(H10^4/$L$9+H8^4/$L$7) -> 380.007 | I26: =(I10^2+I8^2)^2/(I10^4/$L$9+I8^4/$L$7) -> 299.72932
A27: p-value | B27: CS-SY | C27: =_xlfn.T.DIST.2T(ABS(C15),C21) -> 0.76112942 | D27: =_xlfn.T.DIST.2T(ABS(D15),D21) -> 0.53789571 | E27: =_xlfn.T.DIST.2T(ABS(E15),E21) -> 0.39048115 | F27: =_xlfn.T.DIST.2T(ABS(F15),F21) -> 0.66908493 | G27: =_xlfn.T.DIST.2T(ABS(G15),G21) -> 0.89603875 | H27: =_xlfn.T.DIST.2T(ABS(H15),H21) -> 0.8194484 | I27: =_xlfn.T.DIST.2T(ABS(I15),I21) -> 0.60190008
B28: CS-ME | C28: =_xlfn.T.DIST.2T(ABS(C16),C22) -> 0.48786596 | D28: =_xlfn.T.DIST.2T(ABS(D16),D22) -> 0.48490864 | E28: =_xlfn.T.DIST.2T(ABS(E16),E22) -> 0.89960417 | F28: =_xlfn.T.DIST.2T(ABS(F16),F22) -> 0.53613275 | G28: =_xlfn.T.DIST.2T(ABS(G16),G22) -> 0.97832378 | H28: =_xlfn.T.DIST.2T(ABS(H16),H22) -> 0.97817944 | I28: =_xlfn.T.DIST.2T(ABS(I16),I22) -> 0.72692572
B29: CS-CA | C29: =_xlfn.T.DIST.2T(ABS(C17),C23) -> 0.65911188 | D29: =_xlfn.T.DIST.2T(ABS(D17),D23) -> 0.62703078 | E29: =_xlfn.T.DIST.2T(ABS(E17),E23) -> 0.34204689 | F29: =_xlfn.T.DIST.2T(ABS(F17),F23) -> 0.67977153 | G29: =_xlfn.T.DIST.2T(ABS(G17),G23) -> 0.81146538 | H29: =_xlfn.T.DIST.2T(ABS(H17),H23) -> 0.82233509 | I29: =_xlfn.T.DIST.2T(ABS(I17),I23) -> 0.37386996
B30: SY-ME | C30: =_xlfn.T.DIST.2T(ABS(C18),C24) -> 0.22871118 | D30: =_xlfn.T.DIST.2T(ABS(D18),D24) -> 0.92241396 | E30: =_xlfn.T.DIST.2T(ABS(E18),E24) -> 0.50354758 | F30: =_xlfn.T.DIST.2T(ABS(F18),F24) -> 0.18505034 | G30: =_xlfn.T.DIST.2T(ABS(G18),G24) -> 0.91420831 | H30: =_xlfn.T.DIST.2T(ABS(H18),H24) -> 0.72290593 | I30: =_xlfn.T.DIST.2T(ABS(I18),I24) -> 0.92078568
B31: SY-CA | C31: =_xlfn.T.DIST.2T(ABS(C19),C25) -> 0.36215651 | D31: =_xlfn.T.DIST.2T(ABS(D19),D25) -> 0.86883355 | E31: =_xlfn.T.DIST.2T(ABS(E19),E25) -> 0.82768207 | F31: =_xlfn.T.DIST.2T(ABS(F19),F25) -> 0.86248176 | G31: =_xlfn.T.DIST.2T(ABS(G19),G25) -> 0.75435657 | H31: =_xlfn.T.DIST.2T(ABS(H19),H25) -> 0.98480324 | I31: =_xlfn.T.DIST.2T(ABS(I19),I25) -> 0.62241293
B32: ME-CA | C32: =_xlfn.T.DIST.2T(ABS(C20),C26) -> 0.70504941 | D32: =_xlfn.T.DIST.2T(ABS(D20),D26) -> 0.91108552 | E32: =_xlfn.T.DIST.2T(ABS(E20),E26) -> 0.44926886 | F32: =_xlfn.T.DIST.2T(ABS(F20),F26) -> 0.37770281 | G32: =_xlfn.T.DIST.2T(ABS(G20),G26) -> 0.79747511 | H32: =_xlfn.T.DIST.2T(ABS(H20),H26) -> 0.71045027 | I32: =_xlfn.T.DIST.2T(ABS(I20),I26) -> 0.64136155

Sheet Análisis estadístico volúmenes
L1: N° params | M1: 7
C2: mu0 | D2: betaG0 | E2: betaF0 | F2: Yxn | G2: Yxg | H2: Yeg | I2: Yef | J2: N de datos | K2: N fermentaciones | L2: dfi
A3: 100 K | B3: Promedio | C3: ='Pruebas variedades'!S29 -> 0.079638085 | D3: ='Pruebas variedades'!T29 -> 2.3066791 | E3: ='Pruebas variedades'!U29 -> 3.8685831 | F3: ='Pruebas variedades'!AB29 -> 3.7619277 | G3: ='Pruebas variedades'!AC29 -> 6.5702845 | H3: ='Pruebas variedades'!AE29 -> 0.41237867 | I3: ='Pruebas variedades'!AF29 -> 0.48234159 | J3: ='Pruebas variedades'!H20+'Pruebas variedades'!H22+'Pruebas variedades'!H24+'Pruebas variedades'!H26+4 -> 748 | K3: 16 | L3: =J3-$M$1 -> 741
